<?xml version="1.0" encoding="utf-8"?>
<!-- This URDF was automatically created by SolidWorks to URDF Exporter! Originally created by Stephen Brawner (brawner@gmail.com) 
     Commit Version: 1.6.0-1-g15f4949  Build Version: 1.6.7594.29634
     For more information, please see http://wiki.ros.org/sw_urdf_exporter -->
<robot
  name="fdrobot_t1">
  <mujoco>
    <compiler meshdir="../meshes/" balanceinertia="true" discardvisual="false"/>
  </mujoco>
  <!-- <link name="dummy">
  </link>
  <joint name="ddd"
         type="fixed">
    <origin
      xyz="0 0 0"
      rpy="0 0 0" />
    <parent
      link="dummy" />
    <child
      link="base_link" />
  </joint> -->


  <link name="base_link">
    <inertial>
      <origin xyz="-0.04515576 -0.00015716 0.06695607"/>
      <mass value="2.73000000"/>
      <inertia ixx="0.01326015" ixy="-0.00000020" ixz="0.00012671" iyy="0.00829121" iyz="0.00000170" izz="0.01518845"/>
    </inertial>
    <visual>
      <origin
        xyz="0 0 0"
        rpy="0 0 0" />
      <geometry>
        <mesh
          filename="../meshes/base_link.STL" />
      </geometry>
      <material
        name="fd_T1">
        <color
          rgba="1.5 1.5 1.5 1" />
      </material>
    </visual>
    <collision>
      <origin
        xyz="0 0 0"
        rpy="0 0 0" />
      <geometry>
        <mesh
          filename="../meshes/base_link.STL" />
      </geometry>
    </collision>
  </link>
  
  <link name="R_hipY_Link">
    <inertial>
      <origin xyz="-0.00690057 -0.00103408 -0.03299255"/>
      <mass value="0.13500000"/>
      <inertia ixx="0.00010071" ixy="0.00000045" ixz="0.00000523" iyy="0.00017411" iyz="-0.00000567" izz="0.00014227"/>
    </inertial>

    <visual>
      <origin
        xyz="0 0 0"
        rpy="0 0 0" />
      <geometry>
        <mesh
          filename="../meshes/R_hipY_Link.STL" />
      </geometry>
      <material
        name="fd_T1">
        <color
          rgba="0.6 0.6 0.6 1" />
      </material>
    </visual>
    <!-- <collision>
      <origin
        xyz="0 0 0"
        rpy="0 0 0" />
      <geometry>
        <mesh
          filename="../meshes/R_hipY_Link.STL" />
      </geometry>
    </collision> -->
  </link>

  <link name="R_hipR_Link">
    <inertial>
      <origin xyz="0.00515634 -0.00001035 0.00001630"/>
      <mass value="2.13000000"/>
      <inertia ixx="0.00225394" ixy="-0.00000000" ixz="-0.00000000" iyy="0.00235874" iyz="-0.00000017" izz="0.00250818"/>
    </inertial>

    <visual>
      <origin
        xyz="0 0 0"
        rpy="0 0 0" />
      <geometry>
        <mesh
          filename="../meshes/R_hipR_Link.STL" />
      </geometry>
      <material
        name="fd_T1">
        <color
          rgba="0.3 0.3 0.3 1" />
      </material>
    </visual>
    <!-- <collision>
      <origin
        xyz="0 0 0"
        rpy="0 0 0" />
      <geometry>
        <mesh
          filename="../meshes/R_hipR_Link.STL" />
      </geometry>
    </collision> -->
  </link>

  <link name="R_hipP_Link">
    <inertial>
      <origin xyz="-0.05052791 -0.01278962 -0.19348864"/>
      <mass value="1.54000000"/>
      <inertia ixx="0.01782645" ixy="-0.00017759" ixz="-0.00279812" iyy="0.01806249" iyz="-0.00089974" izz="0.00265459"/>
    </inertial>
    <visual>
      <origin
        xyz="0 0 0"
        rpy="0 0 0" />
      <geometry>
        <mesh
          filename="../meshes/R_hipP_Link.STL" />
      </geometry>
      <material
        name="fd_T1">
        <color
          rgba="1.5 1.5 1.5 1" />
      </material>
    </visual>
    <!-- <collision>
      <origin
        xyz="0 0 0"
        rpy="0 0 0" />
      <geometry>
        <mesh
          filename="../meshes/R_hipP_Link.STL" />
      </geometry>
    </collision> -->
  </link>

  <link name="R_knee_Link">
    <inertial>
      <origin xyz="-0.00231537 -0.00881299 -0.14680117"/>
      <mass value="3.02000000"/>
      <inertia ixx="0.03021034" ixy="0.00003810" ixz="0.00189012" iyy="0.03061230" iyz="-0.00041596" izz="0.00277855"/>
    </inertial>
    <visual>
      <origin
        xyz="0 0 0"
        rpy="0 0 0" />
      <geometry>
        <mesh
          filename="../meshes/R_knee_Link.STL" />
      </geometry>
      <material
        name="fd_T1">
        <color
          rgba="1.5 1.5 1.5 1" />
      </material>
    </visual>
    <collision>
      <origin
        xyz="0 0 0"
        rpy="0 0 0" />
      <geometry>
        <mesh
          filename="../meshes/R_knee_Link.STL" />
      </geometry>
    </collision>
  </link>

  <link name="R_ankleY_Link">
    <inertial>
      <origin xyz="-0.00001146 0.00015459 -0.05493229"/>
      <mass value="0.11000000"/>
      <inertia ixx="0.00011813" ixy="-0.00000000" ixz="-0.00000000" iyy="0.00011929" iyz="-0.00000000" izz="0.00001839"/>
    </inertial>

    <visual>
      <origin
        xyz="0 0 0"
        rpy="0 0 0" />
      <geometry>
        <mesh
          filename="../meshes/R_ankleY_Link.STL" />
      </geometry>
      <material
        name="fd_T1">
        <color
          rgba="0.6 0.6 0.6 1" />
      </material>
    </visual>
    <!-- <collision>
      <origin
        xyz="0 0 0"
        rpy="0 0 0" />
      <geometry>
        <mesh
          filename="../meshes/R_ankleY_Link.STL" />
      </geometry>
    </collision> -->
  </link>

  <link name="R_ankleR_Link">
    <inertial>
      <origin xyz="-0.00000060 -0.00000665 0.00000251"/>
      <mass value="0.03200000"/>
      <inertia ixx="0.00000171" ixy="0.00000000" ixz="0.00000000" iyy="0.00000171" iyz="-0.00000000" izz="0.00000272"/>
    </inertial>

    <visual>
      <origin
        xyz="0 0 0"
        rpy="0 0 0" />
      <geometry>
        <mesh
          filename="../meshes/R_ankleR_Link.STL" />
      </geometry>
      <material
        name="fd_T1">
        <color
          rgba="0.6 0.6 0.6 1" />
      </material>
    </visual>
    <!-- <collision>
      <origin
        xyz="0 0 0"
        rpy="0 0 0" />
      <geometry>
        <mesh
          filename="../meshes/R_ankleR_Link.STL" />
      </geometry>
    </collision> -->
  </link>

  <link name="R_ankleP_Link">
    <inertial>
      <origin xyz="0.04013011 -0.00127882 -0.02074679"/>
      <mass value="0.32000000"/>
      <inertia ixx="0.00012583" ixy="-0.00000041" ixz="-0.00000202" iyy="0.00087925" iyz="-0.00000104" izz="0.00093208"/>
    </inertial>

    <visual>
      <origin
        xyz="0 0 0"
        rpy="0 0 0" />
      <geometry>
        <mesh
          filename="../meshes/R_ankleP_Link.STL" />
      </geometry>
      <material
        name="fd_T1">
        <color
          rgba="0.6 0.6 0.6 1" />
      </material>
    </visual>
    <collision>
      <!-- <origin
        xyz="0 0 0"
        rpy="0 0 0" /> -->
      <origin xyz="0.045 0.0 -0.03" rpy="0 -0.014 0" />
      <geometry>
        <!-- <mesh
          filename="../meshes/R_ankleP_Link.STL" /> -->
          <box size=".205 .064 .02" />
      </geometry>
    </collision>
  </link>

  <link name="L_hipY_Link">
    <inertial>
      <origin xyz="-0.00846725 0.00122011 -0.03373783"/>
      <mass value="0.13500000"/>
      <inertia ixx="0.00010071" ixy="-0.00000045" ixz="0.00000523" iyy="0.00017411" iyz="0.00000567" izz="0.00014227"/>
    </inertial>

    <visual>
      <origin
        xyz="0 0 0"
        rpy="0 0 0" />
      <geometry>
        <mesh
          filename="../meshes/L_hipY_Link.STL" />
      </geometry>
      <material
        name="fd_T1">
        <color
          rgba="0.6 0.6 0.6 1" />
      </material>
    </visual>
    <!-- <collision>
      <origin
        xyz="0 0 0"
        rpy="0 0 0" />
      <geometry>
        <mesh
          filename="../meshes/L_hipY_Link.STL" />
      </geometry>
    </collision> -->
  </link>

  <link name="L_hipR_Link">
    <inertial>
      <origin xyz="0.00520149 -0.00000041 0.00001630"/>
      <mass value="2.13000000"/>
      <inertia ixx="0.00225394" ixy="-0.00000000" ixz="-0.00000000" iyy="0.00235874" iyz="-0.00000017" izz="0.00250818"/>
    </inertial>

    <visual>
      <origin
        xyz="0 0 0"
        rpy="0 0 0" />
      <geometry>
        <mesh
          filename="../meshes/L_hipR_Link.STL" />
      </geometry>
      <material
        name="fd_T1">
        <color
          rgba="0.3 0.3 0.3 1" />
      </material>
    </visual>
    <!-- <collision>
      <origin
        xyz="0 0 0"
        rpy="0 0 0" />
      <geometry>
        <mesh
          filename="../meshes/L_hipR_Link.STL" />
      </geometry>
    </collision> -->
  </link>

  <link name="L_hipP_Link">
    <inertial>
      <origin xyz="-0.05056609 0.01269854 -0.19392144"/>
      <mass value="1.54000000"/>
      <inertia ixx="0.01782584" ixy="0.00017752" ixz="-0.00279787" iyy="0.01806181" iyz="0.00089958" izz="0.00265445"/>
    </inertial>

    <visual>
      <origin
        xyz="0 0 0"
        rpy="0 0 0" />
      <geometry>
        <mesh
          filename="../meshes/L_hipP_Link.STL" />
      </geometry>
      <material
        name="fd_T1">
        <color
          rgba="1.5 1.5 1.5 1" />
      </material>
    </visual>
    <!-- <collision>
      <origin
        xyz="0 0 0"
        rpy="0 0 0" />
      <geometry>
        <mesh
          filename="../meshes/L_hipP_Link.STL" />
      </geometry>
    </collision> -->
  </link>

  <link name="L_knee_Link">
    <inertial>
      <origin xyz="-0.00233767 0.00884361 -0.14666966"/>
      <mass value="3.02000000"/>
      <inertia ixx="0.03021031" ixy="-0.00003810" ixz="0.00189012" iyy="0.03061227" iyz="0.00041593" izz="0.00277855"/>
    </inertial>

    <visual>
      <origin
        xyz="0 0 0"
        rpy="0 0 0" />
      <geometry>
        <mesh
          filename="../meshes/L_knee_Link.STL" />
      </geometry>
      <material
        name="fd_T1">
        <color
          rgba="1.5 1.5 1.5 1" />
      </material>
    </visual>
    <collision>
      <origin
        xyz="0 0 0"
        rpy="0 0 0" />
      <geometry>
        <mesh
          filename="../meshes/L_knee_Link.STL" />
      </geometry>
    </collision>
  </link>

  <link name="L_ankleY_Link">
    <inertial>
      <origin xyz="-0.00001144 -0.00010759 -0.05482039"/>
      <mass value="0.11000000"/>
      <inertia ixx="0.00011813" ixy="0.00000000" ixz="-0.00000000" iyy="0.00011929" iyz="0.00000000" izz="0.00001839"/>
    </inertial>

    <visual>
      <origin
        xyz="0 0 0"
        rpy="0 0 0" />
      <geometry>
        <mesh
          filename="../meshes/L_ankleY_Link.STL" />
      </geometry>
      <material
        name="fd_T1">
        <color
          rgba="0.6 0.6 0.6 1" />
      </material>
    </visual>
    <!-- <collision>
      <origin
        xyz="0 0 0"
        rpy="0 0 0" />
      <geometry>
        <mesh
          filename="../meshes/L_ankleY_Link.STL" />
      </geometry>
    </collision> -->
  </link>

  <link name="L_ankleR_Link">
    <inertial>
      <origin xyz="-0.00000060 0.00000342 0.00000251"/>
      <mass value="0.03200000"/>
      <inertia ixx="0.00000171" ixy="-0.00000000" ixz="0.00000000" iyy="0.00000171" iyz="0.00000000" izz="0.00000272"/>
    </inertial>

    <visual>
      <origin
        xyz="0 0 0"
        rpy="0 0 0" />
      <geometry>
        <mesh
          filename="../meshes/L_ankleR_Link.STL" />
      </geometry>
      <material
        name="fd_T1">
        <color
          rgba="0.6 0.6 0.6 1" />
      </material>
    </visual>
    <!-- <collision>
      <origin
        xyz="0 0 0"
        rpy="0 0 0" />
      <geometry>
        <mesh
          filename="../meshes/L_ankleR_Link.STL" />
      </geometry>
    </collision> -->
  </link>

  <link name="L_ankleP_Link">
    <inertial>
      <origin xyz="0.04006882 0.00117942 -0.02075620"/>
      <mass value="0.32000000"/>
      <inertia ixx="0.00012583" ixy="0.00000041" ixz="-0.00000202" iyy="0.00087925" iyz="0.00000104" izz="0.00093208"/>
    </inertial>

    <visual>
      <origin
        xyz="0 0 0"
        rpy="0 0 0" />
      <geometry>
        <mesh
          filename="../meshes/L_ankleP_Link.STL" />
      </geometry>
      <material
        name="fd_T1">
        <color
          rgba="0.6 0.6 0.6 1" />
      </material>
    </visual>
    <collision>
      <!-- <origin
        xyz="0 0 0"
        rpy="0 0 0" /> -->
      <origin xyz="0.045 0.0 -0.03" rpy="0 -0.014 0" />
      <geometry>
        <!-- <mesh
          filename="../meshes/L_ankleP_Link.STL" /> -->
          <box size=".205 .064 .02" />
      </geometry>
    </collision>
  </link>

  <link name="torsoY_Link">
    <inertial>
      <origin xyz="-0.00119987 0.00043033 -0.03764662"/>
      <mass value="1.38000000"/>
      <inertia ixx="0.00234441" ixy="0.00002839" ixz="-0.00008438" iyy="0.00305285" iyz="0.00001229" izz="0.00111019"/>
    </inertial>

    <visual>
      <origin
        xyz="0 0 0"
        rpy="0 0 0" />
      <geometry>
        <mesh
          filename="../meshes/torsoY_Link.STL" />
      </geometry>
      <material
        name="fd_T1">
        <color
          rgba="0.6 0.6 0.6 1" />
      </material>
    </visual>
    <!-- <collision>
      <origin
        xyz="0 0 0"
        rpy="0 0 0" />
      <geometry>
        <mesh
          filename="../meshes/torsoY_Link.STL" />
      </geometry>
    </collision> -->
  </link>

  <link name="torsoR_Link">
    <inertial>
      <origin xyz="-0.00455930 0.00000165 0.00001635"/>
      <mass value="2.13000000"/>
      <inertia ixx="0.00225394" ixy="-0.00000000" ixz="0.00000000" iyy="0.00235874" iyz="0.00000017" izz="0.00250818"/>
    </inertial>

    <visual>
      <origin
        xyz="0 0 0"
        rpy="0 0 0" />
      <geometry>
        <mesh
          filename="../meshes/torsoR_Link.STL" />
      </geometry>
      <material
        name="fd_T1">
        <color
          rgba="0.3 0.3 0.3 1" />
      </material>
    </visual>
    <collision>
      <origin
        xyz="0 0 0"
        rpy="0 0 0" />
      <geometry>
        <mesh
          filename="../meshes/torsoR_Link.STL" />
      </geometry>
    </collision>
  </link>

  <link name="torsoP_Link">
    <inertial>
      <origin xyz="-0 0.00060318 0.18729847"
              rpy="0 0 0"/>
      <mass value="9.46000000"/>
      <inertia ixx="0.102012" ixy="0" ixz="0" iyy="0.0825985" iyz="0" izz="0.0559009"/>
    </inertial>

    <visual>
      <origin
        xyz="0 0 0"
        rpy="0 0 0" />
      <geometry>
        <mesh
          filename="../meshes/torsoP_Link_l.STL" />
      </geometry>
      <material
        name="fd_T1">
        <color
          rgba="1.5 1.5 1.5 1" />
      </material>
    </visual>
    <collision>
      <origin
        xyz="0 0 0"
        rpy="0 0 0" />
      <geometry>
        <mesh
          filename="../meshes/torsoP_Link_l.STL" />
      </geometry>
    </collision>
  </link>

  <link name="R_shoulderY_Link">
    <inertial>
      <origin xyz="0.00139753 -0.00744716 0.02460596"/>
      <mass value="0.06400000"/>
      <inertia ixx="0.00002639" ixy="0.00000026" ixz="-0.00000126" iyy="0.00003460" iyz="0.00000338" izz="0.00002921"/>
    </inertial>

    <visual>
      <origin
        xyz="0 0 0"
        rpy="0 0 0" />
      <geometry>
        <mesh
          filename="../meshes/R_shoulderY_Link.STL" />
      </geometry>
      <material
        name="fd_T1">
        <color
          rgba="0.6 0.6 0.6 1" />
      </material>
    </visual>
    <collision>
      <origin
        xyz="0 0 0"
        rpy="0 0 0" />
      <geometry>
        <mesh
          filename="../meshes/R_shoulderY_Link.STL" />
      </geometry>
    </collision>
  </link>

  <link name="R_shoulderR_Link">
    <inertial>
      <origin xyz="-0.00168346 -0.02917102 -0.00646848"/>
      <mass value="0.77000000"/>
      <inertia ixx="0.00201316" ixy="0.00002573" ixz="0.00000696" iyy="0.00067904" iyz="-0.00046613" izz="0.00189151"/>
    </inertial>

    <visual>
      <origin
        xyz="0 0 0"
        rpy="0 0 0" />
      <geometry>
        <mesh
          filename="../meshes/R_shoulderR_Link.STL" />
      </geometry>
      <material
        name="fd_T1">
        <color
          rgba="1.5 1.5 1.5 1" />
      </material>
    </visual>
    <!-- <collision>
      <origin
        xyz="0 0 0"
        rpy="0 0 0" />
      <geometry>
        <mesh
          filename="../meshes/R_shoulderR_Link.STL" />
      </geometry>
    </collision> -->
  </link>

  <link name="R_elbowY_Link">
    <inertial>
      <origin xyz="-0.00072825 -0.00075054 -0.06022486"/>
      <mass value="0.67300000"/>
      <inertia ixx="0.00119063" ixy="-0.00001630" ixz="0.00000122" iyy="0.00125217" iyz="-0.00000460" izz="0.00025432"/>
    </inertial>

    <visual>
      <origin
        xyz="0 0 0"
        rpy="0 0 0" />
      <geometry>
        <mesh
          filename="../meshes/R_elbowY_Link.STL" />
      </geometry>
      <material
        name="fd_T1">
        <color
          rgba="0.6 0.6 0.6 1" />
      </material>
    </visual>
    <collision>
      <origin
        xyz="0 0 0"
        rpy="0 0 0" />
      <geometry>
        <mesh
          filename="../meshes/R_elbowY_Link.STL" />
      </geometry>
    </collision>
  </link>

  <link name="R_elbowR_Link">
    <inertial>
      <origin xyz="0.00107041 -0.00007189 -0.05273186"/>
      <mass value="1.37300000"/>
      <inertia ixx="0.01006586" ixy="0.00000056" ixz="-0.00002919" iyy="0.01009636" iyz="0.00000090" izz="0.00058052"/>
    </inertial>

    <visual>
      <origin
        xyz="0 0 0"
        rpy="0 0 0" />
      <geometry>
        <mesh
          filename="../meshes/R_elbowR_Link.STL" />
      </geometry>
      <material
        name="fd_T1">
        <color
          rgba="1.5 1.5 1.5 1" />
      </material>
    </visual>
    <collision>
      <origin
        xyz="0 0 0"
        rpy="0 0 0" />
      <geometry>
        <mesh
          filename="../meshes/R_elbowR_Link.STL" />
      </geometry>
    </collision>
  </link>

  <link name="L_shoulderY_Link">
    <inertial>
      <origin xyz="0.00138896 0.00748738 0.02461088"/>
      <mass value="0.06400000"/>
      <inertia ixx="0.00002639" ixy="-0.00000026" ixz="-0.00000126" iyy="0.00003460" iyz="-0.00000338" izz="0.00002921"/>
    </inertial>

    <visual>
      <origin
        xyz="0 0 0"
        rpy="0 0 0" />
      <geometry>
        <mesh
          filename="../meshes/L_shoulderY_Link.STL" />
      </geometry>
      <material
        name="fd_T1">
        <color
          rgba="0.6 0.6 0.6 1" />
      </material>
    </visual>
    <collision>
      <origin
        xyz="0 0 0"
        rpy="0 0 0" />
      <geometry>
        <mesh
          filename="../meshes/L_shoulderY_Link.STL" />
      </geometry>
    </collision>
  </link>

  <link name="L_shoulderR_Link">
    <inertial>
      <origin xyz="-0.00168235 0.03037733 -0.00596837"/>
      <mass value="0.77000000"/>
      <inertia ixx="0.00201289" ixy="-0.00002575" ixz="0.00000699" iyy="0.00067914" iyz="0.00046605" izz="0.00189151"/>
    </inertial>

    <visual>
      <origin
        xyz="0 0 0"
        rpy="0 0 0" />
      <geometry>
        <mesh
          filename="../meshes/L_shoulderR_Link.STL" />
      </geometry>
      <material
        name="fd_T1">
        <color
          rgba="1.5 1.5 1.5 1" />
      </material>
    </visual>
    <!-- <collision>
      <origin
        xyz="0 0 0"
        rpy="0 0 0" />
      <geometry>
        <mesh
          filename="../meshes/L_shoulderR_Link.STL" />
      </geometry>
    </collision> -->
  </link>

  <link name="L_elbowY_Link">
    <inertial>
      <origin xyz="-0.00070115 0.00079643 -0.06022481"/>
      <mass value="0.67300000"/>
      <inertia ixx="0.00119063" ixy="0.00001630" ixz="0.00000123" iyy="0.00125217" iyz="0.00000460" izz="0.00025432"/>
    </inertial>

    <visual>
      <origin
        xyz="0 0 0"
        rpy="0 0 0" />
      <geometry>
        <mesh
          filename="../meshes/L_elbowY_Link.STL" />
      </geometry>
      <material
        name="fd_T1">
        <color
          rgba="0.6 0.6 0.6 1" />
      </material>
    </visual>
    <collision>
      <origin
        xyz="0 0 0"
        rpy="0 0 0" />
      <geometry>
        <mesh
          filename="../meshes/L_elbowY_Link.STL" />
      </geometry>
    </collision>
  </link>

  <link name="L_elbowR_Link">
    <inertial>
      <origin xyz="0.00105610 0.00010278 -0.05285347"/>
      <mass value="1.37300000"/>
      <inertia ixx="0.01006631" ixy="-0.00000218" ixz="-0.00002607" iyy="0.01009704" iyz="-0.00000291" izz="0.00058117"/>
    </inertial>

    <visual>
      <origin
        xyz="0 0 0"
        rpy="0 0 0" />
      <geometry>
        <mesh
          filename="../meshes/L_elbowR_Link.STL" />
      </geometry>
      <material
        name="fd_T1">
        <color
          rgba="1.5 1.5 1.5 1" />
      </material>
    </visual>
    <collision>
      <origin
        xyz="0 0 0"
        rpy="0 0 0" />
      <geometry>
        <mesh
          filename="../meshes/L_elbowR_Link.STL" />
      </geometry>
    </collision>
  </link>

  <link name="neckR_Link">
    <inertial>
      <origin xyz="-0.00000707 0.00000782 0.00000242"/>
      <mass value="0.00680000"/>
      <inertia ixx="0.00000025" ixy="-0.00000000" ixz="0.00000002" iyy="0.00000037" iyz="0.00000000" izz="0.00000050"/>
    </inertial>

    <visual>
      <origin
        xyz="0 0 0"
        rpy="0 0 0" />
      <geometry>
        <mesh
          filename="../meshes/neckR_Link.STL" />
      </geometry>
      <material
        name="fd_T1">
        <color
          rgba="0.6 0.6 0.6 1" />
      </material>
    </visual>
    <collision>
      <origin
        xyz="0 0 0"
        rpy="0 0 0" />
      <geometry>
        <mesh
          filename="../meshes/neckR_Link.STL" />
      </geometry>
    </collision>
  </link>

  <link name="neckP_Link">
    <inertial>
      <origin xyz="0.00548048 0.00000522 0.05939755"/>
      <mass value="0.53000000"/>
      <inertia ixx="0.00051702" ixy="0.00000000" ixz="-0.00002924" iyy="0.00055208" iyz="0.00000000" izz="0.00016741"/>
    </inertial>

    <visual>
      <origin
        xyz="0 0 0"
        rpy="0 0 0" />
      <geometry>
        <mesh
          filename="../meshes/neckP_Link.STL" />
      </geometry>
      <material
        name="fd_T1">
        <color
          rgba="0.6 0.6 0.6 1" />
      </material>
    </visual>
    <!-- <collision>
      <origin
        xyz="0 0 0"
        rpy="0 0 0" />
      <geometry>
        <mesh
          filename="../meshes/neckP_Link.STL" />
      </geometry>
    </collision> -->
  </link>

  <link name="headR_Link">
    <inertial>
      <origin xyz="0.00548048 0.00000522 0.05939755"/>
      <mass value="0.53000000"/>
      <inertia ixx="0.00051702" ixy="0.00000000" ixz="-0.00002924" iyy="0.00055208" iyz="0.00000000" izz="0.00016741"/>
    </inertial>

    <visual>
      <origin
        xyz="0 0 0"
        rpy="0 0 0" />
      <geometry>
        <mesh
          filename="../meshes/headR_Link.STL" />
      </geometry>
      <material
        name="fd_T1">
        <color
          rgba="0.6 0.6 0.6 1" />
      </material>
    </visual>
    <!-- <collision>
      <origin
        xyz="0 0 0"
        rpy="0 0 0" />
      <geometry>
        <mesh
          filename="../meshes/headR_Link.STL" />
      </geometry>
    </collision> -->
  </link>

  <link name="headP_Link">
    <inertial>
      <origin xyz="-0.00000001 -0.00146716 0.04320461"/>
      <mass value="0.10200000"/>
      <inertia ixx="0.00006932" ixy="0.00000000" ixz="0.00000000" iyy="0.00006543" iyz="-0.00001354" izz="0.00003189"/>
    </inertial>

    <visual>
      <origin
        xyz="0 0 0"
        rpy="0 0 0" />
      <geometry>
        <mesh
          filename="../meshes/headP_Link.STL" />
      </geometry>
      <material
        name="fd_T1">
        <color
          rgba="0.6 0.6 0.6 1" />
      </material>
    </visual>
    <!-- <collision>
      <origin
        xyz="0 0 0"
        rpy="0 0 0" />
      <geometry>
        <mesh
          filename="../meshes/headP_Link.STL" />
      </geometry>
    </collision> -->
  </link>

  <link name="headY_Link">
    <inertial>
      <origin xyz="0.01749293 0.00123314 -0.03060852"/>
      <mass value="0.41800000"/>
      <inertia ixx="0.00260869" ixy="0.00001820" ixz="-0.00010934" iyy="0.00274118" iyz="0.00013775" izz="0.00122873"/>
    </inertial>

    <visual>
      <origin
        xyz="0 0 0"
        rpy="0 0 0" />
      <geometry>
        <mesh
          filename="../meshes/headY_Link.STL" />
      </geometry>
      <material
        name="fd_T1">
        <color
          rgba="0.1 0.1 0.1 1" />
      </material>
    </visual>
    <!-- <collision>
      <origin
        xyz="0 0 0"
        rpy="0 0 0" />
      <geometry>
        <mesh
          filename="../meshes/headY_Link.STL" />
      </geometry>
    </collision> -->
  </link>

  <!-- 传感器 -->
  <!-- 上半身IMU -->
  <link name="torso_imu_Link">
      <visual>
        <origin
          xyz="0 0 0"
          rpy="0 0 0" />
          <geometry>
            <sphere radius="0.01"/>
          </geometry>
        <material
          name="body">
          <color
            rgba="0.0 0.8 0.0 1" />
        </material>
      </visual>
  </link>

  <!-- joint -->
  <joint name="leg_right_hipy" type="revolute">
    <origin
      xyz="0.020848 -0.087 -0.008453"
      rpy="0 0 -0.0135049416451496" />
    <parent
      link="base_link" />
    <child
      link="R_hipY_Link" />
    <axis
      xyz="0 0 -1" />
    <limit lower="-0.5" upper="0.5" effort="90" velocity="5" />
    <dynamics damping="0." friction="0." />
  </joint>

  <joint name="leg_right_hipr"
    type="revolute">
    <origin
      xyz="0.00048975139172347 -0.00600000000000003 -0.0630000000000002"
      rpy="0.043848446215598 0 0" />
    <parent
      link="R_hipY_Link" />
    <child
      link="R_hipR_Link" />
    <axis
      xyz="-1 0 0" />
    <limit lower="-0.2" upper="0.5" effort="150" velocity="5" />
    <dynamics damping="0." friction="0." />  
  </joint>

  <joint name="leg_right_hipp"
    type="revolute">
    <origin
      xyz="0.000750248608276216 -0.000605000000000001 0"
      rpy="0 -0.261180468392862 0" />
    <parent
      link="R_hipR_Link" />
    <child
      link="R_hipP_Link" />
    <axis
      xyz="0 -1 0" />
    <limit lower="-1.0" upper="1.0" effort="200" velocity="5" />
    <dynamics damping="0." friction="0." />
  </joint>

  <joint name="leg_right_knee"
    type="revolute">
    <origin
      xyz="-0.0830043203827464 -0.0150331253243573 -0.349140701138534"
      rpy="-0.0602241343835302 0.401634851584503 0.00375354549252053" />
    <parent
      link="R_hipP_Link" />
    <child
      link="R_knee_Link" />
    <axis
      xyz="0 1 0" />
    <limit lower="-0.5" upper="1.0" effort="250" velocity="5" />
    <dynamics damping="0." friction="0." />
  </joint>

  
  <joint name="leg_right_ankley"
    type="fixed">
    <origin
      xyz="0.0157752516698513 -0.00449999999999065 -0.318442600848389"
      rpy="0 -0.0227375486957188 -3.16972512642549E-05" />
    <parent
      link="R_knee_Link" />
    <child
      link="R_ankleY_Link" />
    <axis
      xyz="0 0 -1" />
    <limit lower="-3.14" upper="3.14" effort="148" velocity="5" />
    <dynamics damping="0." friction="0." />
  </joint>

  
  <joint name="leg_right_ankler"
    type="revolute">
    <origin
      xyz="0.00100000000000033 0 -0.109"
      rpy="0.0141734724213509 0 0" />
    <parent
      link="R_ankleY_Link" />
    <child
      link="R_ankleR_Link" />
    <axis
      xyz="-1 0 0" />
    <limit lower="-0.5" upper="0.5" effort="40" velocity="5" />
    <dynamics damping="0." friction="0.1" />
  </joint>

  <joint name="leg_right_anklep"
    type="revolute">
    <origin
      xyz="0 0 0"
      rpy="0 -0.105 0" />
    <parent
      link="R_ankleR_Link" />
    <child
      link="R_ankleP_Link" />
    <axis
      xyz="0 -1 0" />
    <limit lower="-0.5" upper="0.5" effort="80" velocity="5" />
    <dynamics damping="0." friction="0.1" />
  </joint>

  <joint name="leg_left_hipy"
    type="revolute">
    <origin
      xyz="0.020848 0.087 -0.008453"
      rpy="0 0 0.0135049416451357" />
    <parent
      link="base_link" />
    <child
      link="L_hipY_Link" />
    <axis
      xyz="0 0 1" />
    <limit lower="-0.5" upper="0.5" effort="90" velocity="5" />
    <dynamics damping="0." friction="0." />
  </joint>

  <joint name="leg_left_hipr"
    type="revolute">
    <origin
      xyz="0.000489751391723026 0.00600000000000001 -0.063"
      rpy="-0.043848446215598 0 0" />
    <parent
      link="L_hipY_Link" />
    <child
      link="L_hipR_Link" />
    <axis
      xyz="1 0 0" />
    <limit lower="-0.2" upper="0.5" effort="150" velocity="5" />
    <dynamics damping="0." friction="0." />
  </joint>

  <joint name="leg_left_hipp"
    type="revolute">
    <origin
      xyz="0.000750248608277104 0.000605000000000022 0"
      rpy="0 -0.261180468392862 0" />
    <parent
      link="L_hipR_Link" />
    <child
      link="L_hipP_Link" />
    <axis
      xyz="0 -1 0" />
    <limit lower="-1.0" upper="1.0" effort="200" velocity="5" />
    <dynamics damping="0." friction="0." />
  </joint>
  
  <joint name="leg_left_knee"
    type="revolute">
    <origin
      xyz="-0.0830043203827473 0.0150331253243573 -0.349140701138534"
      rpy="0.0602241343835302 0.401634851584503 -0.00375354549252036" />
    <parent
      link="L_hipP_Link" />
    <child
      link="L_knee_Link" />
    <axis
      xyz="0 1 0" />
    <limit lower="-0.5" upper="1.0" effort="250" velocity="5" />
    <dynamics damping="0." friction="0." />
  </joint>

  <joint name="leg_left_ankley"
    type="fixed">
    <origin
      xyz="0.0157752516698508 0.00449999999999064 -0.318442600848389"
      rpy="0 -0.0227375486957189 3.16972512642358E-05" />
    <parent
      link="L_knee_Link" />
    <child
      link="L_ankleY_Link" />
    <axis
      xyz="0 0 1" />
    <limit lower="-3.14" upper="3.14" effort="100" velocity="5" />
    <dynamics damping="0." friction="0." />
  </joint>

  <joint name="leg_left_ankler"
    type="revolute">
    <origin
      xyz="0.00099999999999989 0 -0.109"
      rpy="-0.0141734724213464 0 0" />
    <parent
      link="L_ankleY_Link" />
    <child
      link="L_ankleR_Link" />
    <axis
      xyz="1 0 0" />
    <limit lower="-0.5" upper="0.5" effort="40" velocity="5" />
    <dynamics damping="0." friction="0.1" />
  </joint>

  <joint name="leg_left_anklep"
    type="revolute">
    <origin
      xyz="0 0 0"
      rpy="0. -0.105 0" />
    <parent
      link="L_ankleR_Link" />
    <child
      link="L_ankleP_Link" />
    <axis
      xyz="0 -1 0" />
    <limit lower="-0.5" upper="0.5" effort="80" velocity="5" />
    <dynamics damping="0." friction="0.1" />
  </joint>

  <joint name="torsoy"
    type="fixed">
    <origin
      xyz="-0.00482885444895409 0 0.0660668871255227"
      rpy="-0.00177757094336899 0.471235797337337 -0.00391544437641017" />
    <parent
      link="base_link" />
    <child
      link="torsoY_Link" />
    <axis
      xyz="0 0 -1" />
    <limit lower="-0.3" upper="0.3" effort="100" velocity="5" />
    <dynamics damping="0." friction="0." />
  </joint>

  <joint name="torsor"
    type="fixed">
    <origin
      xyz="0.00223948915506611 0 0.0570000000000375"
      rpy="0 0 0.00348869015895122" />
    <parent
      link="torsoY_Link" />
    <child
      link="torsoR_Link" />
    <axis
      xyz="1 0 0" />
    <limit lower="-0.3" upper="0.3" effort="100" velocity="5" />
    <dynamics damping="0." friction="0." />
  </joint>

  <joint name="torsop"
    type="fixed">
    <origin
      xyz="0 0 0"
      rpy="0 -0.471235797337337 0" />
    <parent
      link="torsoR_Link" />
    <child
      link="torsoP_Link" />
    <axis
      xyz="0 1 0" />
    <limit lower="-0.3" upper="0.3" effort="100" velocity="5" />
    <dynamics damping="0." friction="0." />
  </joint>

  <joint name="arm_right_humeraly"
    type="fixed">
    <origin
      xyz="0.00679205003965233 -0.130034221981293 0.260802775890447"
      rpy="0.773265524729611 0.0436641122998923 -0.0446927051419999" />
    <parent
      link="torsoP_Link" />
    <child
      link="R_shoulderY_Link" />
    <axis
      xyz="0 0 1" />
    <limit lower="-1.2" upper="2.3" effort="100" velocity="5" />
    <dynamics damping="0." friction="0." />
  </joint>
  
  <joint name="arm_right_humeralr"
    type="fixed">
    <origin
      xyz="-0.00184028682785486 -0.0110000000000007 0.0379999999999982"
      rpy="0.187255211743365 0 0" />
    <parent
      link="R_shoulderY_Link" />
    <child
      link="R_shoulderR_Link" />
    <axis
      xyz="-1 0 0" />
    <limit lower="-0.15" upper="3.14" effort="100" velocity="5" />
    <dynamics damping="0." friction="0." />
  </joint>

  <joint name="arm_right_elbow"
    type="fixed">
    <origin
      xyz="0.000899999999998791 -0.109107858457711 -0.0422898950432765"
      rpy="-0.300381134466514 -1.07418834704058 -1.23206342857936" />
    <parent
      link="R_shoulderR_Link" />
    <child
      link="R_elbowY_Link" />
    <axis
      xyz="0 0 -1" />
    <limit lower="-3.14" upper="3.14" effort="100" velocity="5" />
    <dynamics damping="0." friction="0." />
  </joint>

  <joint name="arm_right_wristr"
    type="fixed">
    <origin
      xyz="-0.00155283809991813 -0.000385608396491044 -0.126700000000002"
      rpy="-0.0330072191527965 0 0.243401496663781" />
    <parent
      link="R_elbowY_Link" />
    <child
      link="R_elbowR_Link" />
    <axis
      xyz="1 0 0" />
    <limit lower="-0." upper="1.0" effort="100" velocity="5" />
    <dynamics damping="0." friction="0." />
  </joint>

  <joint name="arm_left_humeraly"
    type="fixed">
    <origin
      xyz="0.00679205000316596 0.130034221980678 0.260802775872372"
      rpy="-0.773265524729577 0.0436641122998908 0.0446927051420018" />
    <parent
      link="torsoP_Link" />
    <child
      link="L_shoulderY_Link" />
    <axis
      xyz="0 0 -1" />
    <limit lower="-1.2" upper="2.3" effort="250" velocity="5" />
    <dynamics damping="0." friction="0." />
  </joint>

  <joint name="arm_left_humeralr"
    type="fixed">
    <origin
      xyz="-0.00184028682785486 0.0110000000000007 0.0379999999999983"
      rpy="-0.187255211743365 0 0" />
    <parent
      link="L_shoulderY_Link" />
    <child
      link="L_shoulderR_Link" />
    <axis
      xyz="1 0 0" />
    <limit lower="-0.15" upper="3.14" effort="100" velocity="5" />
    <dynamics damping="0." friction="0." />
  </joint>

  <joint name="arm_left_elbow"
    type="fixed">
    <origin
      xyz="0.000899999999998791 0.109107858457711 -0.0422898950432766"
      rpy="0.300381134466522 -1.07418834704058 1.23206342857935" />
    <parent
      link="L_shoulderR_Link" />
    <child
      link="L_elbowY_Link" />
    <axis
      xyz="0 0 1" />
    <limit lower="-3.14" upper="3.14" effort="100" velocity="5" />
    <dynamics damping="0." friction="0." />
  </joint>

  <joint name="arm_left_wristr"
    type="fixed">
    <origin
      xyz="-0.0015528380999178 0.000385608396491044 -0.126699999999998"
      rpy="0.033007219152796 0 -0.243401496663778" />
    <parent
      link="L_elbowY_Link" />
    <child
      link="L_elbowR_Link" />
    <axis
      xyz="-1 0 0" />
    <limit lower="-0." upper="1.0" effort="100" velocity="5" />
    <dynamics damping="0." friction="0." />
  </joint>

  <joint name="head_tilt"
    type="fixed">
    <origin
      xyz="-0.0449090000962271 -0.000734685599718894 0.271461388844217"
      rpy="0 -0.0864162517805711 0" />
    <parent
      link="torsoP_Link" />
    <child
      link="neckR_Link" />
    <axis
      xyz="-0.996268438784403 0 0.0863087358387758" />
    <limit lower="-3.14" upper="3.14" effort="100" velocity="5" />
    <dynamics damping="0." friction="0." />
  </joint>

  <joint name="head_flex"
    type="fixed">
    <origin
      xyz="0 0 0"
      rpy="0 0 0" />
    <parent
      link="neckR_Link" />
    <child
      link="neckP_Link" />
    <axis
      xyz="0 1 0" />
    <limit lower="-3.14" upper="3.14" effort="100" velocity="5" />
    <dynamics damping="0." friction="0." />
  </joint>

  <joint name="head_r"
    type="fixed">
    <origin
      xyz="0.00882322255880874 0 0.107640144661502"
      rpy="-0.071377159748209 0.0864163749872467 0" />
    <parent
      link="neckP_Link" />
    <child
      link="headR_Link" />
    <axis
      xyz="-0.999999999999997 0 0" />
    <limit lower="-3.14" upper="3.14" effort="100" velocity="5" />
    <dynamics damping="0." friction="0." />
  </joint>

  <joint name="head_p"
    type="fixed">
    <origin
      xyz="0 0 0"
      rpy="0 0 0" />
    <parent
      link="headR_Link" />
    <child
      link="headP_Link" />
    <axis
      xyz="0 -0.996322731412509 -0.0856797226344629" />
    <limit lower="-3.14" upper="3.14" effort="100" velocity="5" />
    <dynamics damping="0." friction="0." />
  </joint>

  <joint name="head_y"
    type="fixed">
    <origin
      xyz="0 -0.00234203820859034 0.0785883251954749"
      rpy="0 -0.000885935251467676 0.0103008042991836" />
    <parent
      link="headP_Link" />
    <child
      link="headY_Link" />
    <axis
      xyz="0 0.0856751758147071 -0.996323122410154" />
    <limit lower="-3.14" upper="3.14" effort="100" velocity="5" />
    <dynamics damping="0." friction="0." />
  </joint>
  <!--傳感器-->
  <!--头上IMU-->
  <joint name="torso_imu" type="fixed">
    <origin
      xyz="0. 0. 0.26"
      rpy="0 0 0" />
    <parent link="torsoP_Link" />
    <child link="torso_imu_Link" />
  </joint>
</robot>
